Workbook

Sheet START HERE
B1: JCB EDS LAB — MATERIAL DATA
B2: This one file is the whole database. The portal reads it. You edit it like any spreadsheet.
B4: THE ONLY THREE THINGS YOU EVER DO
B5: 1. ADD A NEW MATERIAL → go to the Parts tab, type a new row at the bottom. That is all.
B6: 2. REMOVE A MATERIAL → go to the Parts tab, set Active to No. (Do not delete the row — it keeps the history.)
B7: 3. RECORD STOCK IN / OUT → go to the Movements tab, add a row at the bottom.
B9: WHAT EACH TAB IS FOR
B10: Parts The catalogue. One row per material. You add and retire rows here.
B11: Movements Every receipt and issue, one row each. Only ever ADD rows. Never edit or delete an old one.
B12: LiveStock Calculated automatically. Do not type in it. This is what the portal shows.
B13: Users Who is an Engineer, a Lab Admin, or a Manager. Change a role by changing one word.
B14: Procurement Every PR and PO you raise, with its stage — the portal reads and writes this tab.
... B30: Yellow cells are yours to type in. Grey cells are calculated — leave them alone.

Sheet Parts
A1: PartNo | B1: Description | C1: Category | D1: SubCategory | E1: UOM | F1: Location | G1: Supplier | H1: UnitCost | I1: ReorderRefQty | J1: Active | K1: Notes
A2: MC000RVT1CXX1SQ001 | B2: Revine Tech-1 Sq mm-Cable black | C2: Lab Consumables | D2: Battery Cable | E2: M | G2: REVINE | H2: 12 | I2: 50 | J2: Yes
A3: MC000RVT1CXX1SQ002 | B3: Revine Tech-1 Sq mm-Cable BLUE | C3: Lab Consumables | D3: Battery Cable | E3: M | G3: REVINE | H3: 12 | I3: 50 | J3: Yes
A4: MC000RVT1CXX1SQ003 | B4: Revine Tech-1 Sq mm-Cable RED 1 | C4: Lab Consumables | D4: Battery Cable | E4: M | G4: REVINE | H4: 12 | I4: 50 | J4: Yes
A5: MC000RVT1CXX1SQ004 | B5: Revine Tech-1 Sq mm-Cable | C5: Lab Consumables | D5: Battery Cable | E5: M | G5: REVINE | H5: 12 | I5: 50 | J5: Yes
A6: P_CON_GEN_ASLY_002 | B6: INSULATION TAPE | C6: Lab Consumables | D6: Insulation Tape | E6: NO | F6: UTILITY AREA | G6: ROYAL ENGINEERS AND CONTRACTORS | H6: 10 | I6: 800 | J6: Yes
A7: MC000SWRDTSPXXX001 | B7: Solder Wire-Duratool-SPC22129 | C7: Lab Consumables | D7: Wire | E7: NO | G7: REVINE | I7: 5 | J7: Yes
A8: MC000SFLRVRSXXX001 | B8: Soldering Flux-Revine | C8: Lab Consumables | D8: Soldering Wire | E8: NO | G8: REVINE | H8: 101 | I8: 10 | J8: Yes
A9: MC000IPCFLFLXXX001 | B9: Insulation Pierc Cli-Fluke-FLK-TP82 | C9: Tools | D9: WH Misc | E9: NO | G9: REVINE | H9: 9282 | I9: 2 | J9: Yes
A10: MC000TCNRVSTXXX001 | B10: Terminal Connector-Revine | C10: Wiring Harness Components | D10: Connector | E10: NO | G10: REVINE | H10: 20 | I10: 100 | J10: Yes
A11: MC000RVT1CXX2SQ001 | B11: Revine Tech-1sqmm,2 sqm HST | C11: Lab Consumables | D11: HST | E11: M | G11: REVINE | H11: 13 | I11: 5 | J11: Yes
A12: MC000RVTXXJCXX001 | B12: Revine Tech JUMPER CABLE M TO | C12: Lab Consumables | D12: Battery Cable | E12: M | G12: REVINE | H12: 7 | I12: 100 | J12: Yes
A13: MC000RVTXXJCXX002 | B13: Revine Tech---Jumper Cable- M TO F | C13: Lab Consumables | D13: Battery Cable | E13: M | G13: REVINE | H13: 9 | I13: 100 | J13: Yes
A14: MC000RVTXXJCXX003 | B14: Revine Tech-Jumper Cable--F TO F | C14: Lab Consumables | D14: Battery Cable | E14: M | G14: REVINE | H14: 7 | I14: 100 | J14: Yes
A15: MC000CBLRVXXXXX001 | B15: Cable Label-Revine Tech 240 PCS | C15: Lab Consumables | D15: Battery Cable | E15: NO | G15: REVINE | H15: 1063 | I15: 1 | J15: Yes
A16: M2000A06SC04AA0001 | B16: MISCE STO SCOP BLAC 700 STORAGE BOX | C16: Tools | D16: WH Misc | E16: NO | G16: REVINE | H16: 24000 | I16: 1 | J16: Yes
A17: MC00001A1XXXXX001 | B17: WIRE CLA 0.5 - - WIRE - 0.5 SQ.MM | C17: Lab Consumables | D17: Wire | E17: M | G17: BALAJI EXTRUSIONS & CABLES PVT.LTD | H17: 5.05 | I17: 2000 | J17: Yes
A18: MC00001A2XXXXX001 | B18: WIRE CLA 0.75 - - WIRE - 0.75 SQ.MM | C18: Lab Consumables | D18: Wire | E18: M | G18: BALAJI EXTRUSIONS & CABLES PVT.LTD | H18: 7.53 | I18: 2000 | J18: Yes
A19: MC00001A3XXXXX001 | B19: WIRE CLA 1 SQ - - WIRE - 1 SQ.MM | C19: Lab Consumables | D19: Wire | E19: M | G19: BALAJI EXTRUSIONS & CABLES PVT.LTD | H19: 9.88 | I19: 2000 | J19: Yes
... A27: MC00001B1XXXXX001 | B27: WIRE CLA 8 SQ - - WIRE- 8 SQ.MM | C27: Lab Consumables | D27: Wire | E27: M | G27: BALAJI EXTRUSIONS & CABLES PVT.LTD | H27: 89.06 | I27: 600 | J27: Yes
A28: MC000ACZAUN7IG 9001 | B28: Molex ServiceGrade Hand Crimp Tool for Open Barrel | C28: Tools | D28: WH Misc | E28: NO | G28: RS Components& Controls (I) Ltd. | I28: 2 | J28: Yes
A29: MC000AAOAVO2IH 4001 8 | B29: RS PRO Wire Stripper 0.6mm Min 2.6mm Max 5-1/2 | C29: Tools | D29: Wire | E29: NO | G29: RS Components& Controls (I) Ltd. | I29: 1 | J29: Yes
A30: MC000ADBAFO6XX X001 | B30: Knipex 95 31 Ratchet Cable Cutters | C30: Tools | D30: Battery Cable | E30: NO | G30: RS Components& Controls (I) Ltd. | I30: 1 | J30: Yes
A31: MC000ACZAF07IH7 001 | B31: Knipex PreciForce® Hand Ratcheting Crimp Tool for | C31: Tools | D31: WH Misc | E31: NO | G31: RS Components& Controls (I) Ltd. | I31: 1 | J31: Yes
A32: MC000ADAAFO7IH 8001 | B32: Knipex Crimping Tool 220 mm Overall | C32: Tools | D32: WH Misc | E32: NO | G32: RS Components& Controls (I) Ltd. | I32: 1 | J32: Yes
A33: MC000ACZAWO5X XX001 | B33: Crimp Tool DT Series HD10 Series HD30 Series H | C33: Tools | D33: WH Misc | E33: NO | G33: RS Components& Controls (I) Ltd. | I33: 1 | J33: Yes
A34: P_CON_TOOL_RS_219 | C34: Tools | D34: WH Misc | E34: NO | G34: RS Components& Controls (I) Ltd. | H34: 40900 | I34: 2 | J34: Yes
A35: P_CON_ELCC_GEN_071 | B35: Battery Cable 1C X 16 mm² | C35: Lab Consumables | D35: Battery Cable | E35: NO | F35: EMC CUPBOARD | G35: MOTHERSON SUMI WIRING INDIA ( M274 | H35: 228 | I35: 50 | J35: Yes
A36: P_CON_ELCC_GEN_072 | B36: Battery Cable 1 C X 35 mm² | C36: Lab Consumables | D36: Battery Cable | E36: NO | F36: EMC CUPBOARD | G36: MOTHERSON SUMI WIRING INDIA ( M274 | H36: 532 | I36: 50 | J36: Yes
A37: P_CON_ELCC_GEN_073 | B37: Battery Cable 1 C X 70 mm² | C37: Lab Consumables | D37: Battery Cable | E37: NO | F37: EMC CUPBOARD | G37: MOTHERSON SUMI WIRING INDIA ( M274 | H37: 975 | I37: 50 | J37: Yes
A38: 0010 P_SER_ITSE_AMC_035-SOFTWARE AMC | B38: Renewal Acrobat Pro | C38: Miscellaneous | D38: WH Misc | E38: AU | G38: Sujata Computers Pvt Ltd ( SP0303 | H38: 39000 | I38: 1 | J38: Yes
A39: P_C_CD/2024/006_01 | B39: SEFRAM7204 6000cts handheld digital MM | C39: Tools | D39: WH Misc | E39: NO | G39: RS Components& Controls (I) Ltd. | H39: 12910 | I39: 3 | J39: Yes
A40: P_C_CD/2024/005_01 | B40: Regulated DC Power Supply RL 03203 | C40: Tools | D40: WH Misc | E40: NO | G40: MOGLI LABS INDIA PVT LTD | H40: 47700 | I40: 2 | J40: Yes
A41: 7208/0024 | B41: OUNTERWEIGHT 35E 4WD PAI | C41: Lab Consumables | D41: WH Misc | E41: NO | G41: MOTHERSON SUMI WIRING INDIA ( M274 | H41: 1598 | I41: 50 | J41: Yes
A42: 7208/0023 | B42: OUNTERWEIGHT 35E 4WD PAI | C42: Lab Consumables | D42: WH Misc | E42: NO | G42: MOTHERSON SUMI WIRING INDIA ( M274 | H42: 1598 | I42: 50 | J42: Yes
A43: 7254/1006 | B43: G/Y Trirated 10MM | C43: Lab Consumables | D43: WH Misc | E43: NO | G43: MOTHERSON SUMI WIRING INDIA ( M274 | H43: 278 | I43: 50 | J43: Yes
A44: 7254/0406 | B44: 4 MM SQ. CABLE TRI -RATED CK GR-YE | C44: Lab Consumables | D44: Battery Cable | E44: NO | G44: MOTHERSON SUMI WIRING INDIA ( M274 | H44: 104 | I44: 50 | J44: Yes
A45: 7241/0065 | B45: FUSEHOLDER FIXING PLATE | C45: Lab Consumables | D45: Fuse | E45: NO | G45: MOTHERSON SUMI WIRING INDIA ( M274 | H45: 30.54 | I45: 50 | J45: Yes
A46: 7000/3217 | B46: HEATSHRINK SLEEVE PLAIN Rev.Lel.-01 | C46: Lab Consumables | D46: HST | E46: NO | G46: MOTHERSON SUMI WIRING INDIA ( M274 | H46: 173.4 | I46: 50 | J46: Yes
A47: 717/20129 | B47: TERMINAL BOOT | C47: Lab Consumables | D47: Terminal | E47: NO | G47: MOTHERSON SUMI WIRING INDIA ( M274 | H47: 72.26 | I47: 50 | J47: Yes
...

Sheet Movements
A1: Date | B1: PartNo | C1: Type | D1: Qty | E1: Reference | F1: UnitCost | G1: By | H1: Reason | I1: EntryId
A2: 45351 | B2: P_C_CD/2024/005_01 | C2: RECEIPT | D2: 2 | E2: 9700008666 | F2: 47700 | G2: lab.store@jcb.com
A3: 45357 | B3: P_C_CD/2024/006_01 | C3: RECEIPT | D3: 3 | E3: 9700008677 | F3: 12910 | G3: lab.store@jcb.com
A4: 45467 | B4: 0010 P_SER_ITSE_AMC_035-SOFTWARE AMC | C4: RECEIPT | D4: 1 | E4: 9700008919 | F4: 39000 | G4: lab.store@jcb.com
A5: 45510 | B5: P_CON_ELCC_GEN_071 | C5: RECEIPT | D5: 50 | E5: 9700009002 | F5: 228 | G5: lab.store@jcb.com
A6: 45510 | B6: P_CON_ELCC_GEN_072 | C6: RECEIPT | D6: 50 | E6: 9700009002 | F6: 532 | G6: lab.store@jcb.com
A7: 45510 | B7: P_CON_ELCC_GEN_073 | C7: RECEIPT | D7: 50 | E7: 9700009002 | F7: 975 | G7: lab.store@jcb.com
A8: 45680 | B8: 7208/0024 | C8: RECEIPT | D8: 50 | E8: 9700009294 | F8: 1598 | G8: lab.store@jcb.com
A9: 45680 | B9: 7208/0023 | C9: RECEIPT | D9: 50 | E9: 9700009294 | F9: 1598 | G9: lab.store@jcb.com
A10: 45680 | B10: 7254/1006 | C10: RECEIPT | D10: 50 | E10: 9700009294 | F10: 278 | G10: lab.store@jcb.com
A11: 45680 | B11: 7254/0406 | C11: RECEIPT | D11: 50 | E11: 9700009294 | F11: 104 | G11: lab.store@jcb.com
A12: 45680 | B12: 7241/0065 | C12: RECEIPT | D12: 50 | E12: 9700009294 | F12: 30.54 | G12: lab.store@jcb.com
A13: 45680 | B13: 7000/3217 | C13: RECEIPT | D13: 50 | E13: 9700009294 | F13: 108.45 | G13: lab.store@jcb.com
... A46: 45680 | B46: 7207/1406 | C46: RECEIPT | D46: 50 | E46: 9700009294 | F46: 97.5 | G46: lab.store@jcb.com
A47: 45901 | B47: MC000ACZAUN7IG 9001 | C47: RECEIPT | D47: 2 | E47: 9700009838 | G47: lab.store@jcb.com
A48: 45901 | B48: MC000AAOAVO2IH 4001 8 | C48: RECEIPT | D48: 1 | E48: 9700009838 | G48: lab.store@jcb.com
A49: 45901 | B49: MC000ADBAFO6XX X001 | C49: RECEIPT | D49: 1 | E49: 9700009838 | G49: lab.store@jcb.com
A50: 45901 | B50: MC000ACZAF07IH7 001 | C50: RECEIPT | D50: 1 | E50: 9700009838 | G50: lab.store@jcb.com
A51: 45901 | B51: MC000ADAAFO7IH 8001 | C51: RECEIPT | D51: 1 | E51: 9700009838 | G51: lab.store@jcb.com
A52: 45901 | B52: MC000ACZAWO5X XX001 | C52: RECEIPT | D52: 1 | E52: 9700009838 | G52: lab.store@jcb.com
A53: 45901 | B53: P_CON_TOOL_RS_219 | C53: RECEIPT | D53: 2 | E53: 9700008285 | F53: 40900 | G53: lab.store@jcb.com
A54: 45901 | B54: 7219/0494 | C54: RECEIPT | D54: 3 | G54: lab.store@jcb.com
A55: 45901 | B55: 7219/0493 | C55: RECEIPT | D55: 3 | G55: lab.store@jcb.com
A56: 45901 | B56: 7201/1137 | C56: RECEIPT | D56: 50 | G56: lab.store@jcb.com
A57: 45901 | B57: 7219/0494 | C57: RECEIPT | D57: 1 | E57: FOC_TE_15 | G57: lab.store@jcb.com
A58: 45901 | B58: 402/R5392 | C58: RECEIPT | D58: 1 | E58: RIG MATERIAL_STU_XP | G58: lab.store@jcb.com
A59: 45901 | B59: 402/RX2039 | C59: RECEIPT | D59: 1 | E59: RIG MATERIAL_STU_XP | G59: lab.store@jcb.com
A60: 45901 | B60: 402/R5384 | C60: RECEIPT | D60: 3 | E60: RIG MATERIAL_STU_XP | G60: lab.store@jcb.com
A61: 45901 | B61: 334/E1468 | C61: RECEIPT | D61: 1 | E61: RIG MATERIAL_STU_XP | G61: lab.store@jcb.com
A62: 45901 | B62: 334/E1467 | C62: RECEIPT | D62: 1 | E62: RIG MATERIAL_STU_XP | G62: lab.store@jcb.com
A63: 45901 | B63: 402/R5326 | C63: RECEIPT | D63: 1 | E63: RIG MATERIAL_STU_XP | G63: lab.store@jcb.com
A64: 45901 | B64: 403/W7443 | C64: RECEIPT | D64: 1 | E64: RIG MATERIAL_STU_XP | G64: lab.store@jcb.com
A65: 45901 | B65: 402/R5324 | C65: RECEIPT | D65: 1 | E65: RIG MATERIAL_STU_XP | G65: lab.store@jcb.com
A66: 45901 | B66: 728/J8518 | C66: RECEIPT | D66: 1 | E66: RIG MATERIAL_STU_XP | G66: lab.store@jcb.com
A67: 45901 | B67: MC000SCVMMMJJ002 | C67: RECEIPT | D67: 600 | E67: 9700010133 | F67: 27.3 | G67: lab.store@jcb.com
A68: 45901 | B68: MC000SCMVAQJJ001 | C68: RECEIPT | D68: 300 | E68: 9700010133 | F68: 32.4 | G68: lab.store@jcb.com
A69: 45901 | B69: MC000SCAAYUJJ001 | C69: RECEIPT | D69: 150 | E69: 9700010133 | F69: 43 | G69: lab.store@jcb.com
A70: 45901 | B70: MC000SCBBILJJ001 | C70: RECEIPT | D70: 150 | E70: 9700010133 | F70: 57.3 | G70: lab.store@jcb.com
A71: 45901 | B71: MC000SCCCOPJJ001 | C71: RECEIPT | D71: 300 | E71: 9700010133 | F71: 93.2 | G71: lab.store@jcb.com
A72: 45901 | B72: MC000SCQQPOJJ001 | C72: RECEIPT | D72: 150 | E72: 9700010133 | F72: 129 | G72: lab.store@jcb.com
...

Sheet LiveStock
A1: PartNo | B1: Description | C1: UOM | D1: Location | E1: OnHand | F1: ReorderRefQty | G1: Status
A2: MC000RVT1CXX1SQ001 | B2: Revine Tech-1 Sq mm-Cable black | C2: M | E2: =SUMIFS(Movements!$D$2:$D$20000,Movements!$B$2:$B$20000,$A2,Movements!$C$2:$C$20000,"RECEIPT")+SUMIFS(Movements!$D$2:$D$20000,Movements!$B$2:$B$20000,$A2,Movements!$C$2:$C$20000,"RETURN")+SUMIFS(Movements!$D$2:$D$20000,Movements!$B$2:$B$20000,$A2,Movements!$C$2:$C$20000,"ADJUST+")-SUMIFS(Movements!$D$2:$D$20000,Movements!$B$2:$B$20000,$A2,Movements!$C$2:$C$20000,"ISSUE")-SUMIFS(Movements!$D$2:$D$20000,Movements!$B$2:$B$20000,$A2,Movements!$C$2:$C$20000,"SCRAP")-SUMIFS(Movements!$D$2:$D$20000,Movements!$B$2:$B$20000,$A2,Movements!$C$2:$C$20000,"ADJUST-") | F2: 50 | G2: =IF($E2<=0,"OUT OF STOCK",IF(AND($F2>0,$E2<=$F2*0.2),"LOW STOCK","IN STOCK"))
A3: MC000RVT1CXX1SQ002 | B3: Revine Tech-1 Sq mm-Cable BLUE | C3: M | E3: =SUMIFS(Movements!$D$2:$D$20000,Movements!$B$2:$B$20000,$A3,Movements!$C$2:$C$20000,"RECEIPT")+SUMIFS(Movements!$D$2:$D$20000,Movements!$B$2:$B$20000,$A3,Movements!$C$2:$C$20000,"RETURN")+SUMIFS(Movements!$D$2:$D$20000,Movements!$B$2:$B$20000,$A3,Movements!$C$2:$C$20000,"ADJUST+")-SUMIFS(Movements!$D$2:$D$20000,Movements!$B$2:$B$20000,$A3,Movements!$C$2:$C$20000,"ISSUE")-SUMIFS(Movements!$D$2:$D$20000,Movements!$B$2:$B$20000,$A3,Movements!$C$2:$C$20000,"SCRAP")-SUMIFS(Movements!$D$2:$D$20000,Movements!$B$2:$B$20000,$A3,Movements!$C$2:$C$20000,"ADJUST-") | F3: 50 | G3: =IF($E3<=0,"OUT OF STOCK",IF(AND($F3>0,$E3<=$F3*0.2),"LOW STOCK","IN STOCK"))
A4: MC000RVT1CXX1SQ003 | B4: Revine Tech-1 Sq mm-Cable RED 1 | C4: M | E4: =SUMIFS(Movements!$D$2:$D$20000,Movements!$B$2:$B$20000,$A4,Movements!$C$2:$C$20000,"RECEIPT")+SUMIFS(Movements!$D$2:$D$20000,Movements!$B$2:$B$20000,$A4,Movements!$C$2:$C$20000,"RETURN")+SUMIFS(Movements!$D$2:$D$20000,Movements!$B$2:$B$20000,$A4,Movements!$C$2:$C$20000,"ADJUST+")-SUMIFS(Movements!$D$2:$D$20000,Movements!$B$2:$B$20000,$A4,Movements!$C$2:$C$20000,"ISSUE")-SUMIFS(Movements!$D$2:$D$20000,Movements!$B$2:$B$20000,$A4,Movements!$C$2:$C$20000,"SCRAP")-SUMIFS(Movements!$D$2:$D$20000,Movements!$B$2:$B$20000,$A4,Movements!$C$2:$C$20000,"ADJUST-") | F4: 50 | G4: =IF($E4<=0,"OUT OF STOCK",IF(AND($F4>0,$E4<=$F4*0.2),"LOW STOCK","IN STOCK"))
A5: MC000RVT1CXX1SQ004 | B5: Revine Tech-1 Sq mm-Cable | C5: M | E5: =SUMIFS(Movements!$D$2:$D$20000,Movements!$B$2:$B$20000,$A5,Movements!$C$2:$C$20000,"RECEIPT")+SUMIFS(Movements!$D$2:$D$20000,Movements!$B$2:$B$20000,$A5,Movements!$C$2:$C$20000,"RETURN")+SUMIFS(Movements!$D$2:$D$20000,Movements!$B$2:$B$20000,$A5,Movements!$C$2:$C$20000,"ADJUST+")-SUMIFS(Movements!$D$2:$D$20000,Movements!$B$2:$B$20000,$A5,Movements!$C$2:$C$20000,"ISSUE")-SUMIFS(Movements!$D$2:$D$20000,Movements!$B$2:$B$20000,$A5,Movements!$C$2:$C$20000,"SCRAP")-SUMIFS(Movements!$D$2:$D$20000,Movements!$B$2:$B$20000,$A5,Movements!$C$2:$C$20000,"ADJUST-") | F5: 50 | G5: =IF($E5<=0,"OUT OF STOCK",IF(AND($F5>0,$E5<=$F5*0.2),"LOW STOCK","IN STOCK"))
A6: P_CON_GEN_ASLY_002 | B6: INSULATION TAPE | C6: NO | D6: UTILITY AREA | E6: =SUMIFS(Movements!$D$2:$D$20000,Movements!$B$2:$B$20000,$A6,Movements!$C$2:$C$20000,"RECEIPT")+SUMIFS(Movements!$D$2:$D$20000,Movements!$B$2:$B$20000,$A6,Movements!$C$2:$C$20000,"RETURN")+SUMIFS(Movements!$D$2:$D$20000,Movements!$B$2:$B$20000,$A6,Movements!$C$2:$C$20000,"ADJUST+")-SUMIFS(Movements!$D$2:$D$20000,Movements!$B$2:$B$20000,$A6,Movements!$C$2:$C$20000,"ISSUE")-SUMIFS(Movements!$D$2:$D$20000,Movements!$B$2:$B$20000,$A6,Movements!$C$2:$C$20000,"SCRAP")-SUMIFS(Movements!$D$2:$D$20000,Movements!$B$2:$B$20000,$A6,Movements!$C$2:$C$20000,"ADJUST-") | F6: 800 | G6: =IF($E6<=0,"OUT OF STOCK",IF(AND($F6>0,$E6<=$F6*0.2),"LOW STOCK","IN STOCK"))
A7: MC000SWRDTSPXXX001 | B7: Solder Wire-Duratool-SPC22129 | C7: NO | E7: =SUMIFS(Movements!$D$2:$D$20000,Movements!$B$2:$B$20000,$A7,Movements!$C$2:$C$20000,"RECEIPT")+SUMIFS(Movements!$D$2:$D$20000,Movements!$B$2:$B$20000,$A7,Movements!$C$2:$C$20000,"RETURN")+SUMIFS(Movements!$D$2:$D$20000,Movements!$B$2:$B$20000,$A7,Movements!$C$2:$C$20000,"ADJUST+")-SUMIFS(Movements!$D$2:$D$20000,Movements!$B$2:$B$20000,$A7,Movements!$C$2:$C$20000,"ISSUE")-SUMIFS(Movements!$D$2:$D$20000,Movements!$B$2:$B$20000,$A7,Movements!$C$2:$C$20000,"SCRAP")-SUMIFS(Movements!$D$2:$D$20000,Movements!$B$2:$B$20000,$A7,Movements!$C$2:$C$20000,"ADJUST-") | F7: 5 | G7: =IF($E7<=0,"OUT OF STOCK",IF(AND($F7>0,$E7<=$F7*0.2),"LOW STOCK","IN STOCK"))
A8: MC000SFLRVRSXXX001 | B8: Soldering Flux-Revine | C8: NO | E8: =SUMIFS(Movements!$D$2:$D$20000,Movements!$B$2:$B$20000,$A8,Movements!$C$2:$C$20000,"RECEIPT")+SUMIFS(Movements!$D$2:$D$20000,Movements!$B$2:$B$20000,$A8,Movements!$C$2:$C$20000,"RETURN")+SUMIFS(Movements!$D$2:$D$20000,Movements!$B$2:$B$20000,$A8,Movements!$C$2:$C$20000,"ADJUST+")-SUMIFS(Movements!$D$2:$D$20000,Movements!$B$2:$B$20000,$A8,Movements!$C$2:$C$20000,"ISSUE")-SUMIFS(Movements!$D$2:$D$20000,Movements!$B$2:$B$20000,$A8,Movements!$C$2:$C$20000,"SCRAP")-SUMIFS(Movements!$D$2:$D$20000,Movements!$B$2:$B$20000,$A8,Movements!$C$2:$C$20000,"ADJUST-") | F8: 10 | G8: =IF($E8<=0,"OUT OF STOCK",IF(AND($F8>0,$E8<=$F8*0.2),"LOW STOCK","IN STOCK"))
A9: MC000IPCFLFLXXX001 | B9: Insulation Pierc Cli-Fluke-FLK-TP82 | C9: NO | E9: =SUMIFS(Movements!$D$2:$D$20000,Movements!$B$2:$B$20000,$A9,Movements!$C$2:$C$20000,"RECEIPT")+SUMIFS(Movements!$D$2:$D$20000,Movements!$B$2:$B$20000,$A9,Movements!$C$2:$C$20000,"RETURN")+SUMIFS(Movements!$D$2:$D$20000,Movements!$B$2:$B$20000,$A9,Movements!$C$2:$C$20000,"ADJUST+")-SUMIFS(Movements!$D$2:$D$20000,Movements!$B$2:$B$20000,$A9,Movements!$C$2:$C$20000,"ISSUE")-SUMIFS(Movements!$D$2:$D$20000,Movements!$B$2:$B$20000,$A9,Movements!$C$2:$C$20000,"SCRAP")-SUMIFS(Movements!$D$2:$D$20000,Movements!$B$2:$B$20000,$A9,Movements!$C$2:$C$20000,"ADJUST-") | F9: 2 | G9: =IF($E9<=0,"OUT OF STOCK",IF(AND($F9>0,$E9<=$F9*0.2),"LOW STOCK","IN STOCK"))
A10: MC000TCNRVSTXXX001 | B10: Terminal Connector-Revine | C10: NO | E10: =SUMIFS(Movements!$D$2:$D$20000,Movements!$B$2:$B$20000,$A10,Movements!$C$2:$C$20000,"RECEIPT")+SUMIFS(Movements!$D$2:$D$20000,Movements!$B$2:$B$20000,$A10,Movements!$C$2:$C$20000,"RETURN")+SUMIFS(Movements!$D$2:$D$20000,Movements!$B$2:$B$20000,$A10,Movements!$C$2:$C$20000,"ADJUST+")-SUMIFS(Movements!$D$2:$D$20000,Movements!$B$2:$B$20000,$A10,Movements!$C$2:$C$20000,"ISSUE")-SUMIFS(Movements!$D$2:$D$20000,Movements!$B$2:$B$20000,$A10,Movements!$C$2:$C$20000,"SCRAP")-SUMIFS(Movements!$D$2:$D$20000,Movements!$B$2:$B$20000,$A10,Movements!$C$2:$C$20000,"ADJUST-") | F10: 100 | G10: =IF($E10<=0,"OUT OF STOCK",IF(AND($F10>0,$E10<=$F10*0.2),"LOW STOCK","IN STOCK"))
A11: MC000RVT1CXX2SQ001 | B11: Revine Tech-1sqmm,2 sqm HST | C11: M | E11: =SUMIFS(Movements!$D$2:$D$20000,Movements!$B$2:$B$20000,$A11,Movements!$C$2:$C$20000,"RECEIPT")+SUMIFS(Movements!$D$2:$D$20000,Movements!$B$2:$B$20000,$A11,Movements!$C$2:$C$20000,"RETURN")+SUMIFS(Movements!$D$2:$D$20000,Movements!$B$2:$B$20000,$A11,Movements!$C$2:$C$20000,"ADJUST+")-SUMIFS(Movements!$D$2:$D$20000,Movements!$B$2:$B$20000,$A11,Movements!$C$2:$C$20000,"ISSUE")-SUMIFS(Movements!$D$2:$D$20000,Movements!$B$2:$B$20000,$A11,Movements!$C$2:$C$20000,"SCRAP")-SUMIFS(Movements!$D$2:$D$20000,Movements!$B$2:$B$20000,$A11,Movements!$C$2:$C$20000,"ADJUST-") | F11: 5 | G11: =IF($E11<=0,"OUT OF STOCK",IF(AND($F11>0,$E11<=$F11*0.2),"LOW STOCK","IN STOCK"))
A12: MC000RVTXXJCXX001 | B12: Revine Tech JUMPER CABLE M TO | C12: M | E12: =SUMIFS(Movements!$D$2:$D$20000,Movements!$B$2:$B$20000,$A12,Movements!$C$2:$C$20000,"RECEIPT")+SUMIFS(Movements!$D$2:$D$20000,Movements!$B$2:$B$20000,$A12,Movements!$C$2:$C$20000,"RETURN")+SUMIFS(Movements!$D$2:$D$20000,Movements!$B$2:$B$20000,$A12,Movements!$C$2:$C$20000,"ADJUST+")-SUMIFS(Movements!$D$2:$D$20000,Movements!$B$2:$B$20000,$A12,Movements!$C$2:$C$20000,"ISSUE")-SUMIFS(Movements!$D$2:$D$20000,Movements!$B$2:$B$20000,$A12,Movements!$C$2:$C$20000,"SCRAP")-SUMIFS(Movements!$D$2:$D$20000,Movements!$B$2:$B$20000,$A12,Movements!$C$2:$C$20000,"ADJUST-") | F12: 100 | G12: =IF($E12<=0,"OUT OF STOCK",IF(AND($F12>0,$E12<=$F12*0.2),"LOW STOCK","IN STOCK"))
A13: MC000RVTXXJCXX002 | B13: Revine Tech---Jumper Cable- M TO F | C13: M | E13: =SUMIFS(Movements!$D$2:$D$20000,Movements!$B$2:$B$20000,$A13,Movements!$C$2:$C$20000,"RECEIPT")+SUMIFS(Movements!$D$2:$D$20000,Movements!$B$2:$B$20000,$A13,Movements!$C$2:$C$20000,"RETURN")+SUMIFS(Movements!$D$2:$D$20000,Movements!$B$2:$B$20000,$A13,Movements!$C$2:$C$20000,"ADJUST+")-SUMIFS(Movements!$D$2:$D$20000,Movements!$B$2:$B$20000,$A13,Movements!$C$2:$C$20000,"ISSUE")-SUMIFS(Movements!$D$2:$D$20000,Movements!$B$2:$B$20000,$A13,Movements!$C$2:$C$20000,"SCRAP")-SUMIFS(Movements!$D$2:$D$20000,Movements!$B$2:$B$20000,$A13,Movements!$C$2:$C$20000,"ADJUST-") | F13: 100 | G13: =IF($E13<=0,"OUT OF STOCK",IF(AND($F13>0,$E13<=$F13*0.2),"LOW STOCK","IN STOCK"))
A14: MC000RVTXXJCXX003 | B14: Revine Tech-Jumper Cable--F TO F | C14: M | E14: =SUMIFS(Movements!$D$2:$D$20000,Movements!$B$2:$B$20000,$A14,Movements!$C$2:$C$20000,"RECEIPT")+SUMIFS(Movements!$D$2:$D$20000,Movements!$B$2:$B$20000,$A14,Movements!$C$2:$C$20000,"RETURN")+SUMIFS(Movements!$D$2:$D$20000,Movements!$B$2:$B$20000,$A14,Movements!$C$2:$C$20000,"ADJUST+")-SUMIFS(Movements!$D$2:$D$20000,Movements!$B$2:$B$20000,$A14,Movements!$C$2:$C$20000,"ISSUE")-SUMIFS(Movements!$D$2:$D$20000,Movements!$B$2:$B$20000,$A14,Movements!$C$2:$C$20000,"SCRAP")-SUMIFS(Movements!$D$2:$D$20000,Movements!$B$2:$B$20000,$A14,Movements!$C$2:$C$20000,"ADJUST-") | F14: 100 | G14: =IF($E14<=0,"OUT OF STOCK",IF(AND($F14>0,$E14<=$F14*0.2),"LOW STOCK","IN STOCK"))
A15: MC000CBLRVXXXXX001 | B15: Cable Label-Revine Tech 240 PCS | C15: NO | E15: =SUMIFS(Movements!$D$2:$D$20000,Movements!$B$2:$B$20000,$A15,Movements!$C$2:$C$20000,"RECEIPT")+SUMIFS(Movements!$D$2:$D$20000,Movements!$B$2:$B$20000,$A15,Movements!$C$2:$C$20000,"RETURN")+SUMIFS(Movements!$D$2:$D$20000,Movements!$B$2:$B$20000,$A15,Movements!$C$2:$C$20000,"ADJUST+")-SUMIFS(Movements!$D$2:$D$20000,Movements!$B$2:$B$20000,$A15,Movements!$C$2:$C$20000,"ISSUE")-SUMIFS(Movements!$D$2:$D$20000,Movements!$B$2:$B$20000,$A15,Movements!$C$2:$C$20000,"SCRAP")-SUMIFS(Movements!$D$2:$D$20000,Movements!$B$2:$B$20000,$A15,Movements!$C$2:$C$20000,"ADJUST-") | F15: 1 | G15: =IF($E15<=0,"OUT OF STOCK",IF(AND($F15>0,$E15<=$F15*0.2),"LOW STOCK","IN STOCK"))
A16: M2000A06SC04AA0001 | B16: MISCE STO SCOP BLAC 700 STORAGE BOX | C16: NO | E16: =SUMIFS(Movements!$D$2:$D$20000,Movements!$B$2:$B$20000,$A16,Movements!$C$2:$C$20000,"RECEIPT")+SUMIFS(Movements!$D$2:$D$20000,Movements!$B$2:$B$20000,$A16,Movements!$C$2:$C$20000,"RETURN")+SUMIFS(Movements!$D$2:$D$20000,Movements!$B$2:$B$20000,$A16,Movements!$C$2:$C$20000,"ADJUST+")-SUMIFS(Movements!$D$2:$D$20000,Movements!$B$2:$B$20000,$A16,Movements!$C$2:$C$20000,"ISSUE")-SUMIFS(Movements!$D$2:$D$20000,Movements!$B$2:$B$20000,$A16,Movements!$C$2:$C$20000,"SCRAP")-SUMIFS(Movements!$D$2:$D$20000,Movements!$B$2:$B$20000,$A16,Movements!$C$2:$C$20000,"ADJUST-") | F16: 1 | G16: =IF($E16<=0,"OUT OF STOCK",IF(AND($F16>0,$E16<=$F16*0.2),"LOW STOCK","IN STOCK"))
A17: MC00001A1XXXXX001 | B17: WIRE CLA 0.5 - - WIRE - 0.5 SQ.MM | C17: M | E17: =SUMIFS(Movements!$D$2:$D$20000,Movements!$B$2:$B$20000,$A17,Movements!$C$2:$C$20000,"RECEIPT")+SUMIFS(Movements!$D$2:$D$20000,Movements!$B$2:$B$20000,$A17,Movements!$C$2:$C$20000,"RETURN")+SUMIFS(Movements!$D$2:$D$20000,Movements!$B$2:$B$20000,$A17,Movements!$C$2:$C$20000,"ADJUST+")-SUMIFS(Movements!$D$2:$D$20000,Movements!$B$2:$B$20000,$A17,Movements!$C$2:$C$20000,"ISSUE")-SUMIFS(Movements!$D$2:$D$20000,Movements!$B$2:$B$20000,$A17,Movements!$C$2:$C$20000,"SCRAP")-SUMIFS(Movements!$D$2:$D$20000,Movements!$B$2:$B$20000,$A17,Movements!$C$2:$C$20000,"ADJUST-") | F17: 2000 | G17: =IF($E17<=0,"OUT OF STOCK",IF(AND($F17>0,$E17<=$F17*0.2),"LOW STOCK","IN STOCK"))
A18: MC00001A2XXXXX001 | B18: WIRE CLA 0.75 - - WIRE - 0.75 SQ.MM | C18: M | E18: =SUMIFS(Movements!$D$2:$D$20000,Movements!$B$2:$B$20000,$A18,Movements!$C$2:$C$20000,"RECEIPT")+SUMIFS(Movements!$D$2:$D$20000,Movements!$B$2:$B$20000,$A18,Movements!$C$2:$C$20000,"RETURN")+SUMIFS(Movements!$D$2:$D$20000,Movements!$B$2:$B$20000,$A18,Movements!$C$2:$C$20000,"ADJUST+")-SUMIFS(Movements!$D$2:$D$20000,Movements!$B$2:$B$20000,$A18,Movements!$C$2:$C$20000,"ISSUE")-SUMIFS(Movements!$D$2:$D$20000,Movements!$B$2:$B$20000,$A18,Movements!$C$2:$C$20000,"SCRAP")-SUMIFS(Movements!$D$2:$D$20000,Movements!$B$2:$B$20000,$A18,Movements!$C$2:$C$20000,"ADJUST-") | F18: 2000 | G18: =IF($E18<=0,"OUT OF STOCK",IF(AND($F18>0,$E18<=$F18*0.2),"LOW STOCK","IN STOCK"))
... A33: MC000ACZAWO5X XX001 | B33: Crimp Tool DT Series HD10 Series HD30 Series H | C33: NO | E33: =SUMIFS(Movements!$D$2:$D$20000,Movements!$B$2:$B$20000,$A33,Movements!$C$2:$C$20000,"RECEIPT")+SUMIFS(Movements!$D$2:$D$20000,Movements!$B$2:$B$20000,$A33,Movements!$C$2:$C$20000,"RETURN")+SUMIFS(Movements!$D$2:$D$20000,Movements!$B$2:$B$20000,$A33,Movements!$C$2:$C$20000,"ADJUST+")-SUMIFS(Movements!$D$2:$D$20000,Movements!$B$2:$B$20000,$A33,Movements!$C$2:$C$20000,"ISSUE")-SUMIFS(Movements!$D$2:$D$20000,Movements!$B$2:$B$20000,$A33,Movements!$C$2:$C$20000,"SCRAP")-SUMIFS(Movements!$D$2:$D$20000,Movements!$B$2:$B$20000,$A33,Movements!$C$2:$C$20000,"ADJUST-") | F33: 1 | G33: =IF($E33<=0,"OUT OF STOCK",IF(AND($F33>0,$E33<=$F33*0.2),"LOW STOCK","IN STOCK"))
A34: P_CON_TOOL_RS_219 | C34: NO | E34: =SUMIFS(Movements!$D$2:$D$20000,Movements!$B$2:$B$20000,$A34,Movements!$C$2:$C$20000,"RECEIPT")+SUMIFS(Movements!$D$2:$D$20000,Movements!$B$2:$B$20000,$A34,Movements!$C$2:$C$20000,"RETURN")+SUMIFS(Movements!$D$2:$D$20000,Movements!$B$2:$B$20000,$A34,Movements!$C$2:$C$20000,"ADJUST+")-SUMIFS(Movements!$D$2:$D$20000,Movements!$B$2:$B$20000,$A34,Movements!$C$2:$C$20000,"ISSUE")-SUMIFS(Movements!$D$2:$D$20000,Movements!$B$2:$B$20000,$A34,Movements!$C$2:$C$20000,"SCRAP")-SUMIFS(Movements!$D$2:$D$20000,Movements!$B$2:$B$20000,$A34,Movements!$C$2:$C$20000,"ADJUST-") | F34: 2 | G34: =IF($E34<=0,"OUT OF STOCK",IF(AND($F34>0,$E34<=$F34*0.2),"LOW STOCK","IN STOCK"))
A35: P_CON_ELCC_GEN_071 | B35: Battery Cable 1C X 16 mm² | C35: NO | D35: EMC CUPBOARD | E35: =SUMIFS(Movements!$D$2:$D$20000,Movements!$B$2:$B$20000,$A35,Movements!$C$2:$C$20000,"RECEIPT")+SUMIFS(Movements!$D$2:$D$20000,Movements!$B$2:$B$20000,$A35,Movements!$C$2:$C$20000,"RETURN")+SUMIFS(Movements!$D$2:$D$20000,Movements!$B$2:$B$20000,$A35,Movements!$C$2:$C$20000,"ADJUST+")-SUMIFS(Movements!$D$2:$D$20000,Movements!$B$2:$B$20000,$A35,Movements!$C$2:$C$20000,"ISSUE")-SUMIFS(Movements!$D$2:$D$20000,Movements!$B$2:$B$20000,$A35,Movements!$C$2:$C$20000,"SCRAP")-SUMIFS(Movements!$D$2:$D$20000,Movements!$B$2:$B$20000,$A35,Movements!$C$2:$C$20000,"ADJUST-") | F35: 50 | G35: =IF($E35<=0,"OUT OF STOCK",IF(AND($F35>0,$E35<=$F35*0.2),"LOW STOCK","IN STOCK"))
A36: P_CON_ELCC_GEN_072 | B36: Battery Cable 1 C X 35 mm² | C36: NO | D36: EMC CUPBOARD | E36: =SUMIFS(Movements!$D$2:$D$20000,Movements!$B$2:$B$20000,$A36,Movements!$C$2:$C$20000,"RECEIPT")+SUMIFS(Movements!$D$2:$D$20000,Movements!$B$2:$B$20000,$A36,Movements!$C$2:$C$20000,"RETURN")+SUMIFS(Movements!$D$2:$D$20000,Movements!$B$2:$B$20000,$A36,Movements!$C$2:$C$20000,"ADJUST+")-SUMIFS(Movements!$D$2:$D$20000,Movements!$B$2:$B$20000,$A36,Movements!$C$2:$C$20000,"ISSUE")-SUMIFS(Movements!$D$2:$D$20000,Movements!$B$2:$B$20000,$A36,Movements!$C$2:$C$20000,"SCRAP")-SUMIFS(Movements!$D$2:$D$20000,Movements!$B$2:$B$20000,$A36,Movements!$C$2:$C$20000,"ADJUST-") | F36: 50 | G36: =IF($E36<=0,"OUT OF STOCK",IF(AND($F36>0,$E36<=$F36*0.2),"LOW STOCK","IN STOCK"))
A37: P_CON_ELCC_GEN_073 | B37: Battery Cable 1 C X 70 mm² | C37: NO | D37: EMC CUPBOARD | E37: =SUMIFS(Movements!$D$2:$D$20000,Movements!$B$2:$B$20000,$A37,Movements!$C$2:$C$20000,"RECEIPT")+SUMIFS(Movements!$D$2:$D$20000,Movements!$B$2:$B$20000,$A37,Movements!$C$2:$C$20000,"RETURN")+SUMIFS(Movements!$D$2:$D$20000,Movements!$B$2:$B$20000,$A37,Movements!$C$2:$C$20000,"ADJUST+")-SUMIFS(Movements!$D$2:$D$20000,Movements!$B$2:$B$20000,$A37,Movements!$C$2:$C$20000,"ISSUE")-SUMIFS(Movements!$D$2:$D$20000,Movements!$B$2:$B$20000,$A37,Movements!$C$2:$C$20000,"SCRAP")-SUMIFS(Movements!$D$2:$D$20000,Movements!$B$2:$B$20000,$A37,Movements!$C$2:$C$20000,"ADJUST-") | F37: 50 | G37: =IF($E37<=0,"OUT OF STOCK",IF(AND($F37>0,$E37<=$F37*0.2),"LOW STOCK","IN STOCK"))
A38: 0010 P_SER_ITSE_AMC_035-SOFTWARE AMC | B38: Renewal Acrobat Pro | C38: AU | E38: =SUMIFS(Movements!$D$2:$D$20000,Movements!$B$2:$B$20000,$A38,Movements!$C$2:$C$20000,"RECEIPT")+SUMIFS(Movements!$D$2:$D$20000,Movements!$B$2:$B$20000,$A38,Movements!$C$2:$C$20000,"RETURN")+SUMIFS(Movements!$D$2:$D$20000,Movements!$B$2:$B$20000,$A38,Movements!$C$2:$C$20000,"ADJUST+")-SUMIFS(Movements!$D$2:$D$20000,Movements!$B$2:$B$20000,$A38,Movements!$C$2:$C$20000,"ISSUE")-SUMIFS(Movements!$D$2:$D$20000,Movements!$B$2:$B$20000,$A38,Movements!$C$2:$C$20000,"SCRAP")-SUMIFS(Movements!$D$2:$D$20000,Movements!$B$2:$B$20000,$A38,Movements!$C$2:$C$20000,"ADJUST-") | F38: 1 | G38: =IF($E38<=0,"OUT OF STOCK",IF(AND($F38>0,$E38<=$F38*0.2),"LOW STOCK","IN STOCK"))
A39: P_C_CD/2024/006_01 | B39: SEFRAM7204 6000cts handheld digital MM | C39: NO | E39: =SUMIFS(Movements!$D$2:$D$20000,Movements!$B$2:$B$20000,$A39,Movements!$C$2:$C$20000,"RECEIPT")+SUMIFS(Movements!$D$2:$D$20000,Movements!$B$2:$B$20000,$A39,Movements!$C$2:$C$20000,"RETURN")+SUMIFS(Movements!$D$2:$D$20000,Movements!$B$2:$B$20000,$A39,Movements!$C$2:$C$20000,"ADJUST+")-SUMIFS(Movements!$D$2:$D$20000,Movements!$B$2:$B$20000,$A39,Movements!$C$2:$C$20000,"ISSUE")-SUMIFS(Movements!$D$2:$D$20000,Movements!$B$2:$B$20000,$A39,Movements!$C$2:$C$20000,"SCRAP")-SUMIFS(Movements!$D$2:$D$20000,Movements!$B$2:$B$20000,$A39,Movements!$C$2:$C$20000,"ADJUST-") | F39: 3 | G39: =IF($E39<=0,"OUT OF STOCK",IF(AND($F39>0,$E39<=$F39*0.2),"LOW STOCK","IN STOCK"))
A40: P_C_CD/2024/005_01 | B40: Regulated DC Power Supply RL 03203 | C40: NO | E40: =SUMIFS(Movements!$D$2:$D$20000,Movements!$B$2:$B$20000,$A40,Movements!$C$2:$C$20000,"RECEIPT")+SUMIFS(Movements!$D$2:$D$20000,Movements!$B$2:$B$20000,$A40,Movements!$C$2:$C$20000,"RETURN")+SUMIFS(Movements!$D$2:$D$20000,Movements!$B$2:$B$20000,$A40,Movements!$C$2:$C$20000,"ADJUST+")-SUMIFS(Movements!$D$2:$D$20000,Movements!$B$2:$B$20000,$A40,Movements!$C$2:$C$20000,"ISSUE")-SUMIFS(Movements!$D$2:$D$20000,Movements!$B$2:$B$20000,$A40,Movements!$C$2:$C$20000,"SCRAP")-SUMIFS(Movements!$D$2:$D$20000,Movements!$B$2:$B$20000,$A40,Movements!$C$2:$C$20000,"ADJUST-") | F40: 2 | G40: =IF($E40<=0,"OUT OF STOCK",IF(AND($F40>0,$E40<=$F40*0.2),"LOW STOCK","IN STOCK"))
A41: 7208/0024 | B41: OUNTERWEIGHT 35E 4WD PAI | C41: NO | E41: =SUMIFS(Movements!$D$2:$D$20000,Movements!$B$2:$B$20000,$A41,Movements!$C$2:$C$20000,"RECEIPT")+SUMIFS(Movements!$D$2:$D$20000,Movements!$B$2:$B$20000,$A41,Movements!$C$2:$C$20000,"RETURN")+SUMIFS(Movements!$D$2:$D$20000,Movements!$B$2:$B$20000,$A41,Movements!$C$2:$C$20000,"ADJUST+")-SUMIFS(Movements!$D$2:$D$20000,Movements!$B$2:$B$20000,$A41,Movements!$C$2:$C$20000,"ISSUE")-SUMIFS(Movements!$D$2:$D$20000,Movements!$B$2:$B$20000,$A41,Movements!$C$2:$C$20000,"SCRAP")-SUMIFS(Movements!$D$2:$D$20000,Movements!$B$2:$B$20000,$A41,Movements!$C$2:$C$20000,"ADJUST-") | F41: 50 | G41: =IF($E41<=0,"OUT OF STOCK",IF(AND($F41>0,$E41<=$F41*0.2),"LOW STOCK","IN STOCK"))
A42: 7208/0023 | B42: OUNTERWEIGHT 35E 4WD PAI | C42: NO | E42: =SUMIFS(Movements!$D$2:$D$20000,Movements!$B$2:$B$20000,$A42,Movements!$C$2:$C$20000,"RECEIPT")+SUMIFS(Movements!$D$2:$D$20000,Movements!$B$2:$B$20000,$A42,Movements!$C$2:$C$20000,"RETURN")+SUMIFS(Movements!$D$2:$D$20000,Movements!$B$2:$B$20000,$A42,Movements!$C$2:$C$20000,"ADJUST+")-SUMIFS(Movements!$D$2:$D$20000,Movements!$B$2:$B$20000,$A42,Movements!$C$2:$C$20000,"ISSUE")-SUMIFS(Movements!$D$2:$D$20000,Movements!$B$2:$B$20000,$A42,Movements!$C$2:$C$20000,"SCRAP")-SUMIFS(Movements!$D$2:$D$20000,Movements!$B$2:$B$20000,$A42,Movements!$C$2:$C$20000,"ADJUST-") | F42: 50 | G42: =IF($E42<=0,"OUT OF STOCK",IF(AND($F42>0,$E42<=$F42*0.2),"LOW STOCK","IN STOCK"))
A43: 7254/1006 | B43: G/Y Trirated 10MM | C43: NO | E43: =SUMIFS(Movements!$D$2:$D$20000,Movements!$B$2:$B$20000,$A43,Movements!$C$2:$C$20000,"RECEIPT")+SUMIFS(Movements!$D$2:$D$20000,Movements!$B$2:$B$20000,$A43,Movements!$C$2:$C$20000,"RETURN")+SUMIFS(Movements!$D$2:$D$20000,Movements!$B$2:$B$20000,$A43,Movements!$C$2:$C$20000,"ADJUST+")-SUMIFS(Movements!$D$2:$D$20000,Movements!$B$2:$B$20000,$A43,Movements!$C$2:$C$20000,"ISSUE")-SUMIFS(Movements!$D$2:$D$20000,Movements!$B$2:$B$20000,$A43,Movements!$C$2:$C$20000,"SCRAP")-SUMIFS(Movements!$D$2:$D$20000,Movements!$B$2:$B$20000,$A43,Movements!$C$2:$C$20000,"ADJUST-") | F43: 50 | G43: =IF($E43<=0,"OUT OF STOCK",IF(AND($F43>0,$E43<=$F43*0.2),"LOW STOCK","IN STOCK"))
A44: 7254/0406 | B44: 4 MM SQ. CABLE TRI -RATED CK GR-YE | C44: NO | E44: =SUMIFS(Movements!$D$2:$D$20000,Movements!$B$2:$B$20000,$A44,Movements!$C$2:$C$20000,"RECEIPT")+SUMIFS(Movements!$D$2:$D$20000,Movements!$B$2:$B$20000,$A44,Movements!$C$2:$C$20000,"RETURN")+SUMIFS(Movements!$D$2:$D$20000,Movements!$B$2:$B$20000,$A44,Movements!$C$2:$C$20000,"ADJUST+")-SUMIFS(Movements!$D$2:$D$20000,Movements!$B$2:$B$20000,$A44,Movements!$C$2:$C$20000,"ISSUE")-SUMIFS(Movements!$D$2:$D$20000,Movements!$B$2:$B$20000,$A44,Movements!$C$2:$C$20000,"SCRAP")-SUMIFS(Movements!$D$2:$D$20000,Movements!$B$2:$B$20000,$A44,Movements!$C$2:$C$20000,"ADJUST-") | F44: 50 | G44: =IF($E44<=0,"OUT OF STOCK",IF(AND($F44>0,$E44<=$F44*0.2),"LOW STOCK","IN STOCK"))
A45: 7241/0065 | B45: FUSEHOLDER FIXING PLATE | C45: NO | E45: =SUMIFS(Movements!$D$2:$D$20000,Movements!$B$2:$B$20000,$A45,Movements!$C$2:$C$20000,"RECEIPT")+SUMIFS(Movements!$D$2:$D$20000,Movements!$B$2:$B$20000,$A45,Movements!$C$2:$C$20000,"RETURN")+SUMIFS(Movements!$D$2:$D$20000,Movements!$B$2:$B$20000,$A45,Movements!$C$2:$C$20000,"ADJUST+")-SUMIFS(Movements!$D$2:$D$20000,Movements!$B$2:$B$20000,$A45,Movements!$C$2:$C$20000,"ISSUE")-SUMIFS(Movements!$D$2:$D$20000,Movements!$B$2:$B$20000,$A45,Movements!$C$2:$C$20000,"SCRAP")-SUMIFS(Movements!$D$2:$D$20000,Movements!$B$2:$B$20000,$A45,Movements!$C$2:$C$20000,"ADJUST-") | F45: 50 | G45: =IF($E45<=0,"OUT OF STOCK",IF(AND($F45>0,$E45<=$F45*0.2),"LOW STOCK","IN STOCK"))
A46: 7000/3217 | B46: HEATSHRINK SLEEVE PLAIN Rev.Lel.-01 | C46: NO | E46: =SUMIFS(Movements!$D$2:$D$20000,Movements!$B$2:$B$20000,$A46,Movements!$C$2:$C$20000,"RECEIPT")+SUMIFS(Movements!$D$2:$D$20000,Movements!$B$2:$B$20000,$A46,Movements!$C$2:$C$20000,"RETURN")+SUMIFS(Movements!$D$2:$D$20000,Movements!$B$2:$B$20000,$A46,Movements!$C$2:$C$20000,"ADJUST+")-SUMIFS(Movements!$D$2:$D$20000,Movements!$B$2:$B$20000,$A46,Movements!$C$2:$C$20000,"ISSUE")-SUMIFS(Movements!$D$2:$D$20000,Movements!$B$2:$B$20000,$A46,Movements!$C$2:$C$20000,"SCRAP")-SUMIFS(Movements!$D$2:$D$20000,Movements!$B$2:$B$20000,$A46,Movements!$C$2:$C$20000,"ADJUST-") | F46: 50 | G46: =IF($E46<=0,"OUT OF STOCK",IF(AND($F46>0,$E46<=$F46*0.2),"LOW STOCK","IN STOCK"))
A47: 717/20129 | B47: TERMINAL BOOT | C47: NO | E47: =SUMIFS(Movements!$D$2:$D$20000,Movements!$B$2:$B$20000,$A47,Movements!$C$2:$C$20000,"RECEIPT")+SUMIFS(Movements!$D$2:$D$20000,Movements!$B$2:$B$20000,$A47,Movements!$C$2:$C$20000,"RETURN")+SUMIFS(Movements!$D$2:$D$20000,Movements!$B$2:$B$20000,$A47,Movements!$C$2:$C$20000,"ADJUST+")-SUMIFS(Movements!$D$2:$D$20000,Movements!$B$2:$B$20000,$A47,Movements!$C$2:$C$20000,"ISSUE")-SUMIFS(Movements!$D$2:$D$20000,Movements!$B$2:$B$20000,$A47,Movements!$C$2:$C$20000,"SCRAP")-SUMIFS(Movements!$D$2:$D$20000,Movements!$B$2:$B$20000,$A47,Movements!$C$2:$C$20000,"ADJUST-") | F47: 50 | G47: =IF($E47<=0,"OUT OF STOCK",IF(AND($F47>0,$E47<=$F47*0.2),"LOW STOCK","IN STOCK"))
A48: 7243/0311 | B48: SE RUBBER BOOT CABLE O.D | C48: NO | E48: =SUMIFS(Movements!$D$2:$D$20000,Movements!$B$2:$B$20000,$A48,Movements!$C$2:$C$20000,"RECEIPT")+SUMIFS(Movements!$D$2:$D$20000,Movements!$B$2:$B$20000,$A48,Movements!$C$2:$C$20000,"RETURN")+SUMIFS(Movements!$D$2:$D$20000,Movements!$B$2:$B$20000,$A48,Movements!$C$2:$C$20000,"ADJUST+")-SUMIFS(Movements!$D$2:$D$20000,Movements!$B$2:$B$20000,$A48,Movements!$C$2:$C$20000,"ISSUE")-SUMIFS(Movements!$D$2:$D$20000,Movements!$B$2:$B$20000,$A48,Movements!$C$2:$C$20000,"SCRAP")-SUMIFS(Movements!$D$2:$D$20000,Movements!$B$2:$B$20000,$A48,Movements!$C$2:$C$20000,"ADJUST-") | F48: 50 | G48: =IF($E48<=0,"OUT OF STOCK",IF(AND($F48>0,$E48<=$F48*0.2),"LOW STOCK","IN STOCK"))
A49: 7243/0305 | B49: RUBBER CAP FOR M10&M12 RI Rev.Lel.-01 | C49: NO | D49: L-17 | E49: =SUMIFS(Movements!$D$2:$D$20000,Movements!$B$2:$B$20000,$A49,Movements!$C$2:$C$20000,"RECEIPT")+SUMIFS(Movements!$D$2:$D$20000,Movements!$B$2:$B$20000,$A49,Movements!$C$2:$C$20000,"RETURN")+SUMIFS(Movements!$D$2:$D$20000,Movements!$B$2:$B$20000,$A49,Movements!$C$2:$C$20000,"ADJUST+")-SUMIFS(Movements!$D$2:$D$20000,Movements!$B$2:$B$20000,$A49,Movements!$C$2:$C$20000,"ISSUE")-SUMIFS(Movements!$D$2:$D$20000,Movements!$B$2:$B$20000,$A49,Movements!$C$2:$C$20000,"SCRAP")-SUMIFS(Movements!$D$2:$D$20000,Movements!$B$2:$B$20000,$A49,Movements!$C$2:$C$20000,"ADJUST-") | F49: 50 | G49: =IF($E49<=0,"OUT OF STOCK",IF(AND($F49>0,$E49<=$F49*0.2),"LOW STOCK","IN STOCK"))
A50: 332/S1020 | B50: BOLT AND WASHER 1/4UNC Rev.Lel.-01 | C50: NO | E50: =SUMIFS(Movements!$D$2:$D$20000,Movements!$B$2:$B$20000,$A50,Movements!$C$2:$C$20000,"RECEIPT")+SUMIFS(Movements!$D$2:$D$20000,Movements!$B$2:$B$20000,$A50,Movements!$C$2:$C$20000,"RETURN")+SUMIFS(Movements!$D$2:$D$20000,Movements!$B$2:$B$20000,$A50,Movements!$C$2:$C$20000,"ADJUST+")-SUMIFS(Movements!$D$2:$D$20000,Movements!$B$2:$B$20000,$A50,Movements!$C$2:$C$20000,"ISSUE")-SUMIFS(Movements!$D$2:$D$20000,Movements!$B$2:$B$20000,$A50,Movements!$C$2:$C$20000,"SCRAP")-SUMIFS(Movements!$D$2:$D$20000,Movements!$B$2:$B$20000,$A50,Movements!$C$2:$C$20000,"ADJUST-") | F50: 50 | G50: =IF($E50<=0,"OUT OF STOCK",IF(AND($F50>0,$E50<=$F50*0.2),"LOW STOCK","IN STOCK"))
A51: 401/U6865 | B51: RUBBER CAP FOR M10 TERMINAL | C51: NO | E51: =SUMIFS(Movements!$D$2:$D$20000,Movements!$B$2:$B$20000,$A51,Movements!$C$2:$C$20000,"RECEIPT")+SUMIFS(Movements!$D$2:$D$20000,Movements!$B$2:$B$20000,$A51,Movements!$C$2:$C$20000,"RETURN")+SUMIFS(Movements!$D$2:$D$20000,Movements!$B$2:$B$20000,$A51,Movements!$C$2:$C$20000,"ADJUST+")-SUMIFS(Movements!$D$2:$D$20000,Movements!$B$2:$B$20000,$A51,Movements!$C$2:$C$20000,"ISSUE")-SUMIFS(Movements!$D$2:$D$20000,Movements!$B$2:$B$20000,$A51,Movements!$C$2:$C$20000,"SCRAP")-SUMIFS(Movements!$D$2:$D$20000,Movements!$B$2:$B$20000,$A51,Movements!$C$2:$C$20000,"ADJUST-") | F51: 50 | G51: =IF($E51<=0,"OUT OF STOCK",IF(AND($F51>0,$E51<=$F51*0.2),"LOW STOCK","IN STOCK"))
A52: 7243/0530 | B52: Alternator term cover (+ve) RED | C52: NO | E52: =SUMIFS(Movements!$D$2:$D$20000,Movements!$B$2:$B$20000,$A52,Movements!$C$2:$C$20000,"RECEIPT")+SUMIFS(Movements!$D$2:$D$20000,Movements!$B$2:$B$20000,$A52,Movements!$C$2:$C$20000,"RETURN")+SUMIFS(Movements!$D$2:$D$20000,Movements!$B$2:$B$20000,$A52,Movements!$C$2:$C$20000,"ADJUST+")-SUMIFS(Movements!$D$2:$D$20000,Movements!$B$2:$B$20000,$A52,Movements!$C$2:$C$20000,"ISSUE")-SUMIFS(Movements!$D$2:$D$20000,Movements!$B$2:$B$20000,$A52,Movements!$C$2:$C$20000,"SCRAP")-SUMIFS(Movements!$D$2:$D$20000,Movements!$B$2:$B$20000,$A52,Movements!$C$2:$C$20000,"ADJUST-") | F52: 50 | G52: =IF($E52<=0,"OUT OF STOCK",IF(AND($F52>0,$E52<=$F52*0.2),"LOW STOCK","IN STOCK"))
A53: 7000/3207 | B53: SPLIT CONDUIT TUBING NC | C53: M | E53: =SUMIFS(Movements!$D$2:$D$20000,Movements!$B$2:$B$20000,$A53,Movements!$C$2:$C$20000,"RECEIPT")+SUMIFS(Movements!$D$2:$D$20000,Movements!$B$2:$B$20000,$A53,Movements!$C$2:$C$20000,"RETURN")+SUMIFS(Movements!$D$2:$D$20000,Movements!$B$2:$B$20000,$A53,Movements!$C$2:$C$20000,"ADJUST+")-SUMIFS(Movements!$D$2:$D$20000,Movements!$B$2:$B$20000,$A53,Movements!$C$2:$C$20000,"ISSUE")-SUMIFS(Movements!$D$2:$D$20000,Movements!$B$2:$B$20000,$A53,Movements!$C$2:$C$20000,"SCRAP")-SUMIFS(Movements!$D$2:$D$20000,Movements!$B$2:$B$20000,$A53,Movements!$C$2:$C$20000,"ADJUST-") | F53: 100 | G53: =IF($E53<=0,"OUT OF STOCK",IF(AND($F53>0,$E53<=$F53*0.2),"LOW STOCK","IN STOCK"))
A54: 7205/1000 | B54: 10.0MM2 BROWN BOOTLACE FE Rev.Lel.-02 | C54: NO | E54: =SUMIFS(Movements!$D$2:$D$20000,Movements!$B$2:$B$20000,$A54,Movements!$C$2:$C$20000,"RECEIPT")+SUMIFS(Movements!$D$2:$D$20000,Movements!$B$2:$B$20000,$A54,Movements!$C$2:$C$20000,"RETURN")+SUMIFS(Movements!$D$2:$D$20000,Movements!$B$2:$B$20000,$A54,Movements!$C$2:$C$20000,"ADJUST+")-SUMIFS(Movements!$D$2:$D$20000,Movements!$B$2:$B$20000,$A54,Movements!$C$2:$C$20000,"ISSUE")-SUMIFS(Movements!$D$2:$D$20000,Movements!$B$2:$B$20000,$A54,Movements!$C$2:$C$20000,"SCRAP")-SUMIFS(Movements!$D$2:$D$20000,Movements!$B$2:$B$20000,$A54,Movements!$C$2:$C$20000,"ADJUST-") | F54: 50 | G54: =IF($E54<=0,"OUT OF STOCK",IF(AND($F54>0,$E54<=$F54*0.2),"LOW STOCK","IN STOCK"))
...

Sheet Users
A1: Username | B1: FullName | C1: Role | D1: BusinessUnit | E1: Password | F1: PasswordSetOn | G1: Email
A2: gaurav.shelke | B2: Gaurav Shelke | C2: Lab Lead | D2: EDS
A3: abhijit.dubey | B3: Abhijit Dubey | C3: Lab Admin | D3: BHL INDIA
A4: akshay.aadarsh | B4: Akshay Aadarsh | C4: Engineer | D4: BHL INDIA
A5: akshay.gorakhnath.shejul | B5: Akshay Gorakhnath Shejul | C5: Engineer | D5: BHL INDIA
A6: akshay.kakde | B6: Akshay Kakde | C6: Engineer | D6: BHL INDIA
A7: akshay.pawar | B7: Akshay Pawar | C7: Lab Admin | D7: BHL INDIA
A8: akshay.powar | B8: Akshay Powar | C8: Engineer | D8: BHL INDIA
A9: akshay.rodge | B9: Akshay Rodge | C9: Engineer | D9: BHL INDIA
A10: akshay.titre | B10: Akshay Titre | C10: Engineer | D10: BHL INDIA
A11: alpesh.kumbhar | B11: Alpesh Kumbhar | C11: Engineer | D11: BHL INDIA
A12: amol.savatkar | B12: Amol Savatkar | C12: Engineer | D12: BHL INDIA
A13: anan.jadhav | B13: Anan Jadhav | C13: Engineer | D13: BHL INDIA
... A98: hod.eds | B98: S. Khanduri | C98: Manager | D98: EDS

Sheet Settings
A1: Key | B1: Value | C1: Notes
A2: LowStockPct_Connector | B2: 25 | C2: Connector is LOW when this % or less of ReorderRefQty remains
A3: LowStockPct_Terminal | B3: 20 | C3: Terminal is LOW when this % or less remains
A4: LowStockPct_Default | B4: 20 | C4: All other categories
A5: ReservationExpiryDays | B5: 14 | C5: Reserved stock is released back after this many days
A6: AutoRefreshSeconds | B6: 10 | C6: How often the portal checks this file for changes
A7: OpeningStockCountedOn | C7: Fill in the date you physically counted stock
A8: LabName | B8: JCB EDS Lab, Pune
A9: SupportContact | C9: Who people contact if the portal will not open
A10: HarnessAssemblyCostPerCircuit | B10: 0 | C10: SAMPLE — fill your real ₹ per circuit assembly rate (see Job Card / BUSINESS DECISION REQUIRED)
A11: TransportCostFlat | B11: 200 | C11: SAMPLE — flat transport cost added to every Job Card, in INR
A12: PRPOApprovalLevels | B12: 1 | C12: How many sign-offs a PR/PO needs before Approved. BUSINESS DECISION REQUIRED — set to your real number
A13: ExcelPartRows | B13: =ROWS(tblParts) | C13: Data Health: rows in Parts, counted by Excel. Do not edit.
A14: ExcelMovementRows | B14: =ROWS(tblMoves) | C14: Data Health: rows in Movements, counted by Excel. Do not edit.
A15: ExcelStockTotal | B15: =SUMPRODUCT((tblMoves[Type]="RECEIPT")+(tblMoves[Type]="RETURN")+(tblMoves[Type]="ADJUST+")-(tblMoves[Type]="ISSUE")-(tblMoves[Type]="SCRAP")-(tblMoves[Type]="ADJUST-"),ABS(tblMoves[Qty])) | C15: Data Health: total stock of all parts = signed sum of Movements. Do not edit.

Sheet Procurement
A1: PRNumber | B1: Department | C1: Summary | D1: ServiceType | E1: Qty | F1: DateRaised | G1: RaisedBy | H1: ApprovedBy | I1: ApprovedDate | J1: PONumber | K1: Vendor | L1: POAmount | M1: Stage | N1: PODate | O1: DeliveredDate | P1: Notes | Q1: PRAmount | R1: InvestmentType | S1: POApprovedDate | T1: Ownership | U1: POCopyPath
A2: 800011175 | B2: EDS | C2: 32 CHANNEL RELAY | D2: MATERIAL | E2: 1 | F2: 46027 | M2: PR RAISED
A3: 800011158 | B3: EDS | C3: GEAR COMPONENTS | D3: MATERIAL | E3: 1 | F3: 46027 | M3: PR RAISED
A4: 800011128 | B4: EDS | C4: AUTOMOTIVE TRAINING | D4: SERVICE | E4: 1 | F4: 46027 | M4: DELIVERED (CLOSED)
A5: 800011096 | B5: EDS | C5: WIRE WITH BOBBIN | D5: MATERIAL | E5: 1 | F5: 46027 | M5: PR RAISED
A6: 800011192 | B6: EDS | C6: CLOTH TAPE | D6: MATERIAL | E6: 1 | F6: 46027 | M6: PR RAISED
A7: SAMPLE-PR | B7: SAMPLE | C7: SAMPLE row (keeps column types) | D7: MATERIAL | E7: 1 | F7: 46023.5 | G7: SAMPLE | H7: SAMPLE | I7: 46023.5 | J7: SAMPLE-PO | K7: SAMPLE | L7: 0.5 | M7: REJECTED | N7: 46023.5 | O7: 46023.5 | P7: SAMPLE | Q7: 0.5 | R7: Opex | S7: 46023.5 | T7: SAMPLE | U7: SAMPLE

Sheet Licenses
A1: SoftwareName | B1: Vendor | C1: LicenseType | D1: SeatsTotal | E1: SeatsInUse | F1: ExpiryDate | G1: AnnualCost | H1: Status | I1: Notes
A2: WinCC Professional | B2: Siemens | C2: Perpetual + SUS | D2: 4 | E2: 4 | F2: 46182 | G2: 422000 | H2: =IF($F2="","",IF($F2<TODAY(),"Expired",IF($F2<=TODAY()+45,"Expiring Soon","Active"))) | I2: Sample row — SAMPLE, verify against real renewal
A3: EPLAN Electric P8 | B3: EPLAN Software | C3: Floating | D3: 6 | E3: 4 | F3: 46578 | G3: 339000 | H3: =IF($F3="","",IF($F3<TODAY(),"Expired",IF($F3<=TODAY()+45,"Expiring Soon","Active"))) | I3: Sample row — SAMPLE, verify against real renewal
A4: TIA Portal V18 | B4: Siemens | C4: Perpetual + SUS | D4: 12 | E4: 6 | F4: 46289 | G4: 236000 | H4: =IF($F4="","",IF($F4<TODAY(),"Expired",IF($F4<=TODAY()+45,"Expiring Soon","Active"))) | I4: Sample row — SAMPLE, verify against real renewal

Sheet NewPartRequest
A1: SrNo | B1: RequestNo | C1: RequesterName | D1: Category | E1: SubCategory | F1: PlantCode | G1: PartName | H1: MakeBrand | I1: ModelNo | J1: OtherSpecs | K1: Remarks | L1: UOM | M1: HSNCode | N1: Status | O1: DateRaised
A2: 1 | B2: SAMPLE-NPR-00001 | C2: Sample Engineer | D2: Electrical | E2: Connector | F2: SAMPLE-PLANT | G2: SAMPLE — delete this row | H2: TE Connectivity | I2: AMP-1-967640-1 | J2: 2 way, black | K2: Sample row so the tab is never empty | L2: NO | M2: SAMPLE-HSN | N2: DRAFT | O2: 46282.5

Sheet Invoice
A1: InvoiceNo | B1: InvoiceDate | C1: ToName | D1: CCName | E1: FromName | F1: FromExt | G1: FromMobile | H1: HarnessPartNos | I1: JobDescription | J1: BusinessUnit | K1: BUContact | L1: CostCentre | M1: ApplicationDesc | N1: DetailsOfRequest | O1: NoOfCircuits | P1: DCContact | Q1: DCMobile | R1: JobReceived | S1: StartDate | T1: CompletionDate | U1: MaterialCost | V1: AssemblyCost | W1: TransportCost | X1: TotalCost | Y1: RefRequest | Z1: ImagePath | AA1: Status | AB1: Notes
A2: SAMPLE-INV | B2: 46023.5 | C2: SAMPLE | D2: SAMPLE | E2: SAMPLE | F2: SAMPLE | G2: SAMPLE | H2: SAMPLE | I2: SAMPLE | J2: SAMPLE | K2: SAMPLE | L2: SAMPLE | M2: SAMPLE | N2: SAMPLE row (keeps column types) | O2: 1 | P2: SAMPLE | Q2: SAMPLE | R2: 46023.5 | S2: 46023.5 | T2: 46023.5 | U2: 0.5 | V2: 0.5 | W2: 200.5 | X2: 1.5 | Y2: SAMPLE | Z2: SAMPLE | AA2: SAMPLE | AB2: SAMPLE

Sheet OngoingPurchase
A1: PartNo | B1: Description | C1: QtyRequired | D1: QtyConfirmed | E1: RequestNo | F1: RaisedBy | G1: PRNumber | H1: SupplierNo | I1: SupplierName | J1: Stage | K1: DateRaised | L1: ExpectedDate | M1: Notes
A2: SAMPLE | B2: SAMPLE row (keeps column types) | C2: 1.5 | D2: 0.5 | E2: SAMPLE | F2: SAMPLE | G2: SAMPLE-PR | H2: SAMPLE | I2: SAMPLE | J2: RECEIVED | K2: 46023.5 | L2: 46023.5 | M2: SAMPLE

Sheet Calibration
A1: AssetNo | B1: AssetName | C1: Location | D1: LastCalDate | E1: IntervalMonths | F1: DueDate | G1: Owner | H1: Status | I1: Notes
A2: SAMPLE | B2: SAMPLE row (keeps column types) | C2: SAMPLE | D2: 46023.5 | E2: 12 | F2: 46023.5 | G2: SAMPLE | H2: SAMPLE | I2: SAMPLE

Sheet Requests
A1: RequestNo | B1: Kind | C1: Status | D1: RaisedByEmail | E1: RaisedByName | F1: DateRaised | G1: Machine | H1: ProjectCode | I1: HarnessPartNo | J1: BuildStage | K1: BusinessUnit | L1: CostCentre | M1: BUContact | N1: DCContact | O1: NoOfCircuits | P1: RequiredBy | Q1: ScopeOfWork | R1: ParentRequest | S1: LastUpdated | T1: LastUpdatedBy | U1: History
A2: SAMPLE-REQ-00000 | B2: SAMPLE | C2: COMPLETED | D2: sample@jcb.com | E2: SAMPLE row (keeps column types) | F2: 46023.5 | G2: SAMPLE | H2: SAMPLE | I2: SAMPLE | J2: Proto | K2: SAMPLE | L2: SAMPLE | M2: SAMPLE | N2: SAMPLE | O2: 1 | P2: 46023.5 | Q2: SAMPLE row - Power Apps ignores rows whose key starts with SAMPLE. Do not delete. | R2: SAMPLE | S2: 2026-01-01T12:00:00 | T2: SAMPLE | U2: []

Sheet RequestLines
A1: RequestNo | B1: Sr | C1: PartNo | D1: Description | E1: QtyRequested | F1: QtyReserved | G1: QtyReleased | H1: UOM | I1: LineStatus | J1: UnitCost | K1: StoreLocation | L1: Remarks
A2: SAMPLE-REQ-00000 | B2: 1 | C2: SAMPLE | D2: SAMPLE row (keeps column types) | E2: 1.5 | F2: 0.5 | G2: 0.5 | H2: NO | I2: COMPLETED | J2: 0.5 | K2: SAMPLE | L2: SAMPLE

Sheet POWER APPS
B1: THIS COPY IS FOR THE POWER APPS VERSION OF THE PORTAL
B3: Keep it on OneDrive for Business or a SharePoint document library. Power Apps reads and writes it through the
B4: Excel Online (Business) connector. It is a separate file from the one the HTA uses on the lab PC.
B6: Rows whose first column starts with SAMPLE are there on purpose: Power Apps works out whether a column holds
B7: text, numbers or dates from the data in it, and an empty table makes every column text. The app ignores
B8: every SAMPLE row. Leave them in.
B10: Users has an extra Email column on the right. Leave it blank if each person's Username is the part of their
B11: email address before the @ (gaurav.shelke for gaurav.shelke@jcb.com). Fill it only when that is not true.
B13: When Power Apps first connects it adds a hidden __PowerAppsId__ column to each table. That is normal.
B15: ROLES: one person can hold several roles. Write them in the Role cell separated by commas, for example
B16: 'Engineer, Manager'. The first one is the usual role. Lab Lead and Lab Admin can view every role.
B18: DATA HEALTH: the three Excel* rows at the bottom of Settings are formulas. Leave them; the app compares them
B19: with what it read (About > Data Health).
